Workbook

Sheet Introduction
A18: Introduction: The assessment for Azure security establishes a unified framework of governance, identity, networking, data protection, and operational controls. It strategically aligns with international standards to enhance security maturity, minimize risks, ensure regulatory compliance, and enable secure cloud transformation while supporting business resilience and long-term operational scalability. ------------------------------------------------------------------------------------------------- Sections: 1. Network security - Secures and segments networks, controls traffic, prevents attacks, secures DNS and private connectivity for cloud. 2. Identity Management - Establishes secure identities, authentication, single sign-on, conditional access, managed identities and anomaly monitoring across environments. 3. Privileged Access - Protects administrative accounts and models, enforces least privilege, just-in-time access, privileged workstation controls, and oversight. 4. Data Protection - Discovers, classifies, encrypts, and monitors sensitive data; enforces keys, access controls, and data-loss prevention mechanisms. 5. Asset Management - Maintains inventory, tracks resources, governs service approvals, and enforces approved-service and application usage controls consistently. 6. Logging and Threat Detection - Collects, centralizes, retains logs; enables threat detection, high-quality alerts, SIEM integration, and investigative analytics capabilities. 7. Incident Response - Prepares for, detects, analyzes, contains, and recovers from incidents; automates response and conducts post-incident activities. 8. Posture and Vulnerability Management - Assesses configuration and vulnerabilities, tracks posture, performs scanning, prioritizes remediation, and automates corrective actions continuously. 9. Endpoint Security - Deploys EDR and anti-malware, secures endpoints, monitors behavior, and integrates endpoint telemetry into detection platforms. 10. Backup and Recovery - Ensures backups, validates restores, protects backup integrity, defines RPO/RTO, and supports disaster recovery planning activities. 11. DevOps Security - Integrates security into CI/CD, secures artifacts, enforces SAST/DAST, supply-chain checks, and pipeline hardening through automation. 12. Governance and Strategy - Defines security strategy, governance, roles, policies, multi-cloud strategy, and measurable compliance for sustained assurance oversight. ------------------------------------------------------------------------------------------------- Scope: TBD

Sheet Summary
A1: Sheet Names | B1: Total Controls | C1: Count of Compliant | D1: Count of Partial compliant | E1: Count of Non compliant | F1: Percentage | G1: Scale (out of 5)
A2: Network security | B2: =SUM('Network security'!M2:M100) | C2: =COUNTIF('Network security'!O:O,"Complete") | D2: =COUNTIF('Network security'!O:O,"Partial") | E2: =COUNTIF('Network security'!O:O,"Non-Compliant") | F2: =ROUND(IFERROR((((C2+0.5*D2)/(C2+D2+E2))*100),0), 1) | G2: =ROUND(IFERROR(((F2/100)*5),0), 1)
A3: Identity management | B3: =SUM('Identity management'!M2:M102) | C3: =COUNTIF('Identity management'!O:O,"Complete") | D3: =COUNTIF('Identity management'!O:O,"Partial") | E3: =COUNTIF('Identity management'!O:O,"Non-Compliant") | F3: =ROUND(IFERROR((((C3+0.5*D3)/(C3+D3+E3))*100),0), 1) | G3: =ROUND(IFERROR(((F3/100)*5),0), 1)
A4: Privileged access | B4: =SUM('Privileged access'!L2:L102) | C4: =COUNTIF('Privileged access'!N:N,"Complete") | D4: =COUNTIF('Privileged access'!N:N,"Partial") | E4: =COUNTIF('Privileged access'!N:N,"Non-Compliant") | F4: =ROUND(IFERROR((((C4+0.5*D4)/(C4+D4+E4))*100),0), 1) | G4: =ROUND(IFERROR(((F4/100)*5),0), 1)
A5: Data protection | B5: =SUM('Data protection'!M2:M103) | C5: =COUNTIF('Data protection'!O:O,"Complete") | D5: =COUNTIF('Data protection'!O:O,"Partial") | E5: =COUNTIF('Data protection'!O:O,"Non-Compliant") | F5: =ROUND(IFERROR((((C5+0.5*D5)/(C5+D5+E5))*100),0), 1) | G5: =ROUND(IFERROR(((F5/100)*5),0), 1)
A6: Asset management | B6: =SUM('Asset management'!L2:L100) | C6: =COUNTIF('Asset management'!N:N,"Complete") | D6: =COUNTIF('Asset management'!N:N,"Partial") | E6: =COUNTIF('Asset management'!N:N,"Non-Compliant") | F6: =ROUND(IFERROR((((C6+0.5*D6)/(C6+D6+E6))*100),0), 1) | G6: =ROUND(IFERROR(((F6/100)*5),0), 1)
A7: Logging and threat detection | B7: =SUM('Logging and threat detection'!M2:M105) | C7: =COUNTIF('Logging and threat detection'!O:O,"Complete") | D7: =COUNTIF('Logging and threat detection'!O:O,"Partial") | E7: =COUNTIF('Logging and threat detection'!O:O,"Non-Compliant") | F7: =ROUND(IFERROR((((C7+0.5*D7)/(C7+D7+E7))*100),0), 1) | G7: =ROUND(IFERROR(((F7/100)*5),0), 1)
A8: Incident response | B8: =SUM('Incident response'!L2:L106) | C8: =COUNTIF('Incident response'!N:N,"Complete") | D8: =COUNTIF('Incident response'!N:N,"Partial") | E8: =COUNTIF('Incident response'!N:N,"Non-Compliant") | F8: =ROUND(IFERROR((((C8+0.5*D8)/(C8+D8+E8))*100),0), 1) | G8: =ROUND(IFERROR(((F8/100)*5),0), 1)
A9: Posture and vulnerability manag | B9: =SUM('Posture and vulnerability manag'!M2:M107) | C9: =COUNTIF('Posture and vulnerability manag'!O:O,"Complete") | D9: =COUNTIF('Posture and vulnerability manag'!O:O,"Partial") | E9: =COUNTIF('Posture and vulnerability manag'!O:O,"Non-Compliant") | F9: =ROUND(IFERROR((((C9+0.5*D9)/(C9+D9+E9))*100),0), 1) | G9: =ROUND(IFERROR(((F9/100)*5),0), 1)
A10: Endpoint security | B10: =SUM('Endpoint security'!L2:L100) | C10: =COUNTIF('Endpoint security'!N:N,"Complete") | D10: =COUNTIF('Endpoint security'!N:N,"Partial") | E10: =COUNTIF('Endpoint security'!N:N,"Non-Compliant") | F10: =ROUND(IFERROR((((C10+0.5*D10)/(C10+D10+E10))*100),0), 1) | G10: =ROUND(IFERROR(((F10/100)*5),0), 1)
A11: Backup and recovery | B11: =SUM('Backup and recovery'!L2:L109) | C11: =COUNTIF('Backup and recovery'!N:N,"Complete") | D11: =COUNTIF('Backup and recovery'!N:N,"Partial") | E11: =COUNTIF('Backup and recovery'!N:N,"Non-Compliant") | F11: =ROUND(IFERROR((((C11+0.5*D11)/(C11+D11+E11))*100),0), 1) | G11: =ROUND(IFERROR(((F11/100)*5),0), 1)
A12: DevOps security | B12: =SUM('DevOps security'!L2:L100) | C12: =COUNTIF('DevOps security'!N:N,"Complete") | D12: =COUNTIF('DevOps security'!N:N,"Partial") | E12: =COUNTIF('DevOps security'!N:N,"Non-Compliant") | F12: =ROUND(IFERROR((((C12+0.5*D12)/(C12+D12+E12))*100),0), 1) | G12: =ROUND(IFERROR(((F12/100)*5),0), 1)
A13: Governance and strategy | B13: =SUM('Governance and strategy'!L2:L100) | C13: =COUNTIF('Governance and strategy'!N:N,"Complete") | D13: =COUNTIF('Governance and strategy'!N:N,"Partial") | E13: =COUNTIF('Governance and strategy'!N:N,"Non-Compliant") | F13: =ROUND(IFERROR((((C13+0.5*D13)/(C13+D13+E13))*100),0), 1) | G13: =ROUND(IFERROR(((F13/100)*5),0), 1)
A14: Total | B14: =SUM(B2:B13) | C14: =SUM(C2:C13) | D14: =SUM(D2:D13) | E14: =SUM(E2:E13) | F14: =ROUND(AVERAGE(F2:F13),1)

Sheet Azure Landing Questions
A1: Adoption Evaluation | B1: Options | C1: Response | D1: Score (1/1)
A2: How would you describe your cloud strategy? | B2: Developed as necessary, fragmented Clear and defined Transformational and innovative Requires optimization
A3: Are you responding to any critical business events, such as, datacenter exit, mergers and acquisition, end of support for mission-critical technologies, or response to regulatory compliance change? | B3: Yes No Don't know
A4: What are the critical business events driving your cloud transformation? | B4: Datacenter exit Merger, acquisition, or divestiture Reduction in capital expenses End of support for mission-critical technologies Response to regulatory compliance changes New data sovereignty requirements Reduction of disruptions and improvement of IT stability Report and manage the environmental impact of your business Expanding capacity without migrating because you're not able to move to OpEx or can't deprecate due to business needs
A5: Are there any other motivations that are driving your cloud transformation, other than those driven by critical business events? | B5: Cost savings Reduction in vendor or technical complexity Optimization of internal operations Increase in business agility Scaling to meet market and/or geographic demands Integration of a complex IT portfolio Improved customer experiences and engagements Transformation of products or services Market disruption with new products or services Preparation for, or building new, technical capabilities None of the above Democratization and/or self-service environments
A6: Has your cloud strategy been communicated broadly across the organization? | B6: Yes No, just at the leadership level We are in the process of communicating it Yes, but we need to reinforce the message Don't know
A7: Do you conduct regular cloud strategy reviews with the broader organization? | B7: Yes, consistently Yes, on an adhoc basis No
A8: Have you documented a cloud strategy with multi-year horizon and C-level participation and/or sponsorship? | B8: Yes, at least a 3-year plan Yes, but we haven't put it into action No, I would like to document a strategy
A9: What are the business outcomes driving your cloud transformation? | B9: Increase profitability while driving compliance Accelerate sales, improve customer lifetime value Acquire and retain customers, build a reputation Retain, recruit, and empower employees Meet market growth requirements and environmental sustainability metrics Global reach Performance and reliability None of the above
A10: Do these outcomes have associated business drivers, KPIs, and necessary technical capabilities? | B10: Yes No Don't know
A11: Have you developed a financial model or performed an economic assessment that provides business justification for moving to the cloud? | B11: Yes No Don't know
A12: It's important to understand how to account for cloud costs before you begin a cloud transformation journey. Select your company's model from the following common cloud accounting models. | B12: Cost-center model Profit-center model Charge-back model Showback or awareness-back model Don't know None of the above
A13: Do you understand how your resources need to scale depending on usage, utilization, and demand in a cloud context? | B13: Yes No
... A29: Answer | B29: Score Map
A30: Yes | B30: 1
A31: No | B31: 0
A32: 1 or more option | B32: 1

Sheet Setup-Questions
A1: Question | B1: Response Captured
A2: Do you currently use a CSPM or Defender for Cloud for continuous compliance and posture monitoring?
A3: Is there a SIEM/SOAR platform (like Microsoft Sentinel) collecting and correlating logs from all Azure resources?
A4: Do you have centralized identity management through Microsoft Entra ID with MFA and Conditional Access enforced
A5: Is Privileged Identity Management (PIM) or a similar solution in place for admin access control and elevation
A6: Are subscriptions and management groups organized under a governance model with defined policies and guardrails
A7: Is Azure Policy actively used to enforce configuration baselines and prevent non-compliant deployments?
A8: Are network controls such as firewalls, NSGs, and Private Endpoints configured to restrict external access?
A9: Is data encryption at rest and in transit enforced across all services using managed or customer-managed keys?
A10: Do you use Azure Key Vault or an HSM for secret and key management with access logging enabled?
A11: Are Defender for Servers/Containers/SQL or equivalent workload protections deployed and monitored?
A12: Do you perform vulnerability scanning and patch management for all compute, container, and PaaS workloads
A13: Is there an established incident response process integrated with alerting and automation (playbooks/runbooks)
... A21: Are regulatory and compliance dashboards (CIS, ISO, NIST, PCI, etc.) tracked and reported from Defender for Cloud or another tool

Sheet Network security
A1: Control ID | B1: Control Title | C1: Security Principle | D1: Azure Guidance | E1: MCSB Control ID Mapping | F1: CIS Mapping (v8) | G1: NIST SP 800-53 Mapping | H1: PCI-DSS Mapping (v3.2.1) | I1: CSA CCM Control ID | J1: IANS Azure Mapping | K1: Assessment Question | L1: Evidence to Collect | M1: Evidence Count | N1: Available Evidence Count | O1: Compliance Status | P1: Risk Severity (if non-compliant) | Q1: Implementation Gap | R1: Notes/Comments
A2: CSF-AZ-NS-01 | B2: Establish network segmentation boundaries | C2: Ensure that your virtual network deployment aligns to your enterprise segmentation strategy defined in the GS-2 security control. Any workload that could incur higher risk for the organization should be in isolated virtual networks. | D2: Create a virtual network (VNet) as a fundamental segmentation approach in your Azure network, so resources such as VMs can be deployed into the VNet within a network boundary. To further segment the network, you can create subnets inside VNet for smaller sub-networks. Use network security groups (NSG) as a network layer control to restrict or monitor traffic by port, protocol, source IP address, or destination IP address. Refer to NS-7: Simplify network security configuration to use Adaptive Network Hardening to recommend NSG hardening rules based on threat intelligence and traffic analysis result. You can also use application security groups (ASGs) to simplify complex configuration. Instead of defining policy based on explicit IP addresses in network security groups, ASGs enable you to configure network security as a natural extension of an application's structure, allowing you to group virtual machines and define network security policies based on those groups. | E2: NS-1 | F2: 3.12, 13.4, 4.4 | G2: AC-4, SC-2, SC-7 | H2: 1.1, 1.2, 1.3 | I2: IVS-03 | K2: 1. Are VNets and subnets defined for workload isolation? 2. Are NSGs applied to restrict/monitor traffic? 3. Are ASGs used for simplifying security rules? 4. Are segmentation rules aligned with enterprise segmentation strategy? | L2: 1. Azure VNet/subnet configuration export 2. NSG rule reports 3. ASG definitions 4. Network Hardening recommendations (Defender for Cloud or equivalent tool) 5. Architecture diagram showing segmentation boundaries | M2: 5 | N2: 0 | O2: Non-Compliant
A3: CSF-AZ-NS-02 | B3: Secure cloud native services with network controls | C3: Secure cloud services by establishing a private access point for resources. You should also disable or restrict access from public networks when possible. | D3: Deploy private endpoints for all Azure resources that support the Private Link feature to establish a private access point for the resources. Using Private Link will keep the private connection from routing through the public network. Note: Certain Azure services may also allow private communication through the service endpoint feature, though it is recommended to use Azure Private Link for secure and private access to services hosted on Azure platform. For certain services, you can choose to deploy VNet integration for the service where you can restrict the VNET to establish a private access point for the service. You also have the option to configure the service native network ACL rules or simply disable public network access to block access from public networks. For Azure VMs, unless there is a strong use case, you should avoid assigning public IPs/subnet directly to the VM interface and instead use gateway or load balancer services as the front-end for access by the public network. | E3: NS-2 | F3: 3.12, 4.4 | G3: AC-4, SC-2, SC-7 | H3: 1.1, 1.2, 1.3 | I3: IVS-06 | K3: 1. Are Azure PaaS services (e.g., Storage, SQL, Key Vault) integrated privately with VNets via Private Link or Service Endpoints? 2. Is public access disabled where feasible? 3. Are NSGs or firewall rules applied to restrict access to services? | L3: 1. Azure Private Link/Service Endpoint configuration 2. Firewall and NSG rule sets 3. Azure Policy assignments for restricting public access | M3: 3 | N3: 0 | O3: Partial
A4: CSF-AZ-NS-03 | B4: Deploy firewall at the edge of enterprise network | C4: Deploy a firewall to perform advanced filtering on network traffic to and from external networks. You can also use firewalls between internal segments to support a segmentation strategy. If required, use custom routes for your subnet to override the system route when you need to force the network traffic to go through a network appliance for security control purposes. | D4: Use Azure Firewall to provide fully stateful application layer traffic restriction (such as URL filtering) and/or central management over a large number of enterprise segments or spokes (in a hub/spoke topology). If you have a complex network topology, such as a hub/spoke setup, you may need to create user-defined routes (UDR) to ensure the traffic goes through the desired route. For example, you have the option to use an UDR to redirect egress internet traffic through a specific Azure Firewall or a network virtual appliance. | E4: NS-3 | F4: 4.4, 4.8, 13.10 | G4: AC-4, SC-7, CM-7 | H4: 1.1, 1.2, 1.3 | I4: IVS-08 | K4: 1. Is Azure Firewall deployed for centralized traffic control? 2. Are firewall policies defined with application and network rules? 3. Is Firewall Manager used for policy consistency? 4. Are threat intelligence-based filtering rules enabled? | L4: 1. Azure Firewall configuration and rules export 2. Firewall Manager policy assignments 3. Defender for Cloud recommendations | M4: 3 | N4: 0 | O4: Complete
A5: CSF-AZ-NS-04 | B5: Deploy intrusion detection/intrusion prevention systems (IDS/IPS) | C5: Use network intrusion detection and intrusion prevention systems (IDS/IPS) to inspect the network and payload traffic to or from your workload. Ensure that IDS/IPS is always tuned to provide high-quality alerts to your SIEM solution. | D5: Use Azure Firewall’s IDPS capabilities to protect your virtual network to alert on and/or block traffic to and from known malicious IP addresses and domains. For more in-depth host level detection and prevention capability, deploy host-based IDS/IPS or a host-based endpoint detection and response (EDR) solution, such as Microsoft Defender for Endpoint, at the VM level in conjunction with the network IDS/IPS. | E5: NS-4 | F5: 13.2, 13.3, 13.7, 13.8 | G5: SC-7, SI-4 | H5: 11.4 | I5: IVS-09 | K5: 1. Is IDS/IPS functionality enabled on Azure Firewall Premium or NVA appliances? 2. Is traffic being mirrored to an IDS solution (e.g., via Network Watcher TAP)? 3. Are alerts integrated with SIEM (Microsoft Sentinel)? | L5: 1. IDS/IPS configuration on Azure Firewall or NVAs 2. Logs showing intrusion detection alerts 3. Sentinel integration settings | M5: 3 | N5: 0 | O5: Complete
A6: CSF-AZ-NS-05 | B6: Deploy DDOS protection | C6: Deploy distributed denial of service (DDoS) protection to protect your network and applications from attacks. | D6: DDoS Protection Basic is automatically enabled to protect the Azure underlying platform infrastructure (e.g. Azure DNS) and requires no configuration from the users. For higher levels of protection of your application layer (Layer 7) attacks such as HTTP floods and DNS floods, enable the DDoS standard protection plan on your VNet to protect resources that are exposed to the public networks. | E6: NS-5 | F6: 13.1 | G6: SC-5, SC-7 | H6: 1.1, 1.2, 1.3, 6.6 | I6: IPY-09 | K6: 1. Is Azure DDoS Protection (Basic or Standard) enabled? 2. Are high-risk internet-facing VNets enrolled in DDoS Standard? 3. Are mitigation alerts integrated with monitoring? | L6: 1. DDoS Standard plan assignment in subscription 2. VNet DDoS protection configuration 3. Monitoring/alert logs from Defender for Cloud | M6: 3 | N6: 0 | O6: Partial
A7: CSF-AZ-NS-06 | B7: Deploy web application firewall | C7: Deploy a web application firewall (WAF) and configure the appropriate rules to protect your web applications and APIs from application-specific attacks. | D7: Use web application firewall (WAF) capabilities in Azure Application Gateway, Azure Front Door, and Azure Content Delivery Network (CDN) to protect your applications, services and APIs against application layer attacks at the edge of your network. Set your WAF in "detection" or "prevention mode", depending on your needs and threat landscape. Choose a built-in ruleset, such as OWASP Top 10 vulnerabilities, and tune it to your application needs. | E7: NS-6 | F7: 13.1 | G7: SC-7 | H7: 1.1, 1.2, 1.3 | I7: IVS-07 | K7: 1. Are Azure Application Gateway WAF or Azure Front Door WAF policies deployed? 2. Are managed rule sets enabled and customized as needed? 3. Are logs from WAF integrated into Sentinel? | L7: 1. WAF policy configuration export 2. Rule set assignment (OWASP CRS, custom rules) 3. Log Analytics/Sentinel WAF logs | M7: 3 | N7: 0 | O7: Non-Compliant
A8: CSF-AZ-NS-07 | B8: Simplify network security configuration | C8: When managing a complex network environment, use tools to simplify, centralize and enhance network security management. | D8: Use the following features to simplify the implementation and management of the virtual network, NSG rules, and Azure Firewall rules: 1. Use Azure Virtual Network Manager to group, configure, deploy, and manage virtual networks and NSG rules across regions and subscriptions. 2. Use Microsoft Defender for Cloud Adaptive Network Hardening to recommend NSG hardening rules that further limit ports, protocols and source IPs based on threat intelligence and traffic analysis result. 3. Use Azure Firewall Manager to centralize the firewall policy and route management of the virtual network. To simplify the firewall rules and network security groups implementation, you can also use the Azure Firewall Manager Azure Resource Manager(ARM) template. | E8: NS-7 | F8: 4.4, 4.8 | G8: AC-4, SC-2, SC-7 | H8: 1.1, 1.2, 1.3 | I8: IVS-04 | K8: 1. Is Adaptive Network Hardening enabled in Defender for Cloud? 2. Are NSGs being hardened using recommendations? 3. Is policy-as-code (Azure Policy/Blueprints) applied to enforce security rules? | L8: 1. Adaptive Network Hardening recommendations 2. Azure Policy assignment reports 3. Screenshots of NSG recommendation remediation | M8: 3 | N8: 0 | O8: Non-Compliant
A9: CSF-AZ-NS-08 | B9: Detect and disable insecure services and protocols | C9: Detect and disable insecure services and protocols at the OS, application, or software package layer. Deploy compensating controls if disabling insecure services and protocols are not possible. | D9: Use Microsoft Sentinel’s built-in Insecure Protocol Workbook to discover the use of insecure services and protocols such as SSL/TLSv1, SSHv1, SMBv1, LM/NTLMv1, wDigest, weak ciphers in Kerberos, and Unsigned LDAP Binds. Disable insecure services and protocols that do not meet the appropriate security standard. Note: If disabling insecure services or protocols is not possible, use compensating controls such as blocking access to the resources through network security group, Azure Firewall, or Azure Web Application Firewall to reduce the attack surface. | E9: NS-8 | F9: 4.4, 4.8 | G9: CM-2, CM-6, CM-7 | H9: 4.1, A2.1, A2.2, A2.3 | I9: LOG-03 | K9: 1. Are insecure protocols (e.g., SMBv1, Telnet, RDP over internet) blocked via NSGs or Firewall? 2. Are TLS 1.2+ enforced on services? 3. Are monitoring alerts enabled for deprecated/insecure services? | L9: 1. NSG/Firewall rules blocking insecure ports 2. Service configurations (TLS settings in App Gateway, SQL, Storage) 3. Defender for Cloud insecure protocol findings | M9: 3 | N9: 0 | O9: Partial
A10: CSF-AZ-NS-09 | B10: Connect on-premises or cloud network privately | C10: Use private connections for secure communication between different networks, such as cloud service provider datacenters and on-premises infrastructure in a colocation environment. | D10: For lightweight site-to-site or point-to-site connectivity, use Azure virtual private network (VPN) to create a secure connection between your on-premises site or end-user device and the Azure virtual network. For enterprise-level high performance connections, use Azure ExpressRoute (or Virtual WAN) to connect Azure datacenters and on-premises infrastructure in a co-location environment. When connecting two or more Azure virtual networks together, use virtual network peering. Network traffic between peered virtual networks is private and is kept on the Azure backbone network. | E10: NS-9 | F10: 12.7 | G10: CA-3, AC-17, AC-4 | H10: N/A | I10: LOG-2 | K10: 1. Is ExpressRoute or VPN Gateway used for hybrid connectivity? 2. Are Private Endpoints used for inter-service communication? 3. Is traffic encrypted over private connections? 4. Is forced tunneling configured if required? | L10: 1. ExpressRoute/VPN Gateway configuration 2. Private Link endpoint setup 3. Network architecture diagrams 4. Defender for Cloud hybrid network findings | M10: 4 | N10: 0 | O10: Complete
A11: CSF-AZ-NS-10 | B11: Ensure Domain Name System (DNS) security | C11: Ensure that Domain Name System (DNS) security configuration protects against known risks: 1. Use trusted authoritative and recursive DNS services across your cloud environment to ensure the client (such as operating systems and applications) receives the correct resolution result. 2. Separate the public and private DNS resolution so the DNS resolution process for the private network can be isolated from the public network. 3. Ensure your DNS security strategy also includes mitigations against common attacks, such as dangling DNS, DNS amplifications attacks, DNS poisoning and spoofing, and so on. | D11: Use Azure recursive DNS (usually assigned to your VM through DHCP or preconfigured in the service) or a trusted external DNS server in your workload recursive DNS setup, such as in the VM's operating system or in the application. Use Azure Private DNS for a private DNS zone setup where the DNS resolution process does not leave the virtual network. Use a custom DNS to restrict the DNS resolution to only allow trusted resolution to your client. Use Microsoft Defender for DNS for advanced protection against the following security threats to your workload or your DNS service: Data exfiltration from your Azure resources using DNS tunneling Malware communicating with a command-and-control server Communication with malicious domains, such as phishing and crypto mining DNS attacks in communication with malicious DNS resolvers You can also use Microsoft Defender for App Service to detect dangling DNS records if you decommission an App Service website without removing its custom domain from your DNS registrar. | E11: NS-10 | F11: 4.9, 9.2 | G11: SC-20, SC-21 | H11: N/A | I11: SEF-03 | K11: 1. Is Azure DNS with DNSSEC (where applicable) enabled? 2. Are private DNS zones used for internal name resolution? 3. Are outbound DNS queries filtered (Azure Firewall DNS proxy, custom resolver)? 4. Is SPF/DMARC/DKIM configured for domains? | L11: 1. Azure DNS zone configuration with DNSSEC status 2. Private DNS zone setup documentation 3. Firewall DNS proxy configuration 4. Domain security settings (SPF/DMARC/DKIM) | M11: 4 | N11: 0 | O11: Partial
A12: CSF-AZ-NS-11 | B12: Sensitive ports are not exposed to the internet | C12: Sensitive network ports are not exposed to the internet, including administrative ports (SSH/RDP), database ports and other common management ports. This is typically a good indicator that basic network security hygiene is in place, even if implemented manually. | D12: VMs or load balancers are not in network security groups that expose the following ports: - MongoDB ports 27017 and 27018 - FTP ports 20 or 21 - port 22 - port 3389 - Cassandra ports 7199 or 9160 or 8888 - Elasticsearch/Kibana ports 9200 or 9300 or 5601 - Kafka port 9092 - Memcached port 11211 - MySQL port 3306 - Oracle ports 1521 or 2483 - Postgres port 5432 - Redis port 6379 - Windows SQL Server ports 1433 or 1434 - Telnet port 23" | E12: N/A | F12: N/A | G12: N/A | H12: N/A | I12: N/A | J12: NET-02.1 | K12: Is the organization currently following the Azure Guidance ? | L12: Confirmation of the Assessment question | M12: 1 | O12: Non-Compliant
A13: CSF-AZ-NS-12 | B13: Security groups should not allow excessive port ranges | C13: Cloud networks should minimize potential attack paths by using tightly scoped security group rules, even on non-internet facing resources. One indicator of this is tightly scoped security groups applied to every compute resource that only allow a limited number of inbound ports (e.g., no more than five ports). | D13: Network Security Groups allow no more than five inbound ports Security groups are applied to all VMs/containers, not just subnets | E13: N/A | F13: N/A | G13: N/A | H13: N/A | I13: N/A | J13: NET-03.2 | K13: Is the organization currently following the Azure Guidance ? | L13: Confirmation of the Assessment question | M13: 1 | O13: Complete

Sheet Identity management
A1: Control ID | B1: Control Title | C1: Security Principle | D1: Azure Guidance | E1: MCSB Control ID Mapping | F1: CIS Mapping (v8) | G1: NIST SP 800-53 Mapping | H1: PCI-DSS Mapping (v3.2.1) | I1: CSA CCM Control ID | J1: IANS Azure Mapping | K1: Assessment Question | L1: Evidence to Collect | M1: Evidence Count | N1: Available Evidence Count | O1: Compliance Status | P1: Risk Severity (if non-compliant) | Q1: Implementation Gap | R1: Notes/Comments
A2: CSF-AZ-IM-01 | B2: Use centralized identity and authentication system | C2: Use a centralized identity and authentication system to govern your organization's identities and authentications for cloud and non-cloud resources. | D2: Azure Active Directory (Azure AD) is Azure's identity and authentication management service. You should standardize on Azure AD to govern your organization's identity and authentication in: Microsoft cloud resources, such as Azure Storage, Azure Virtual Machines (Linux and Windows), Azure Key Vault, PaaS, and SaaS applications. Your organization's resources, such as applications on Azure, third-party applications running on your corporate network resources, and third-party SaaS applications. Your enterprise identities in Active Directory by synchronization to Azure AD to ensure a consistent and centrally managed identity strategy. For the Azure services that apply, avoid use of local authentication methods and instead use Azure Active Directory to centralize your service authentications. | E2: IM-1 | F2: 6.7, 12.5 | G2: AC-2, AC-3, IA-2, IA-8 | H2: 7.2, 8.3 | I2: IAM-01, IAM-02, IAM-03 | K2: 1. Are all Azure resources (VMs, SQL, Storage, Key Vault, PaaS) integrated with Azure AD instead of local accounts? 2. Is on-premises Active Directory synchronized with Azure AD using AD Connect or SCIM? 3. Are third-party SaaS applications federated with Azure AD SSO (SAML/OIDC)? | L2: 1. Azure AD tenant configuration screenshot (Azure Portal → Azure Active Directory → Overview). 2. Export of Azure AD Connect sync rules (AD Connect → Synchronization Rules Editor). 3. List of Enterprise Applications integrated with SSO (AzureAD PowerShell: Get-AzureADServicePrincipal) | M2: 3 | O2: Partial
A3: CSF-AZ-IM-02 | B3: Protect identity and authentication systems | C3: Secure your identity and authentication system as a high priority in your organization's cloud security practice. Common security controls include: 1. Restrict privileged roles and accounts 2. Require strong authentication for all privileged access 3. Monitor and audit high risk activities | D3: Use the Azure AD security baseline and the Azure AD Identity Secure Score to evaluate your Azure AD identity security posture, and remediate security and configuration gaps. The Azure AD Identity Secure Score evaluates Azure AD for the following configurations: Use limited administrative roles Turn on user risk policy Designate more than one global admin Enable policy to block legacy authentication Ensure all users can complete multi-factor authentication for secure access Require MFA for administrative roles Enable self-service password reset Do not expire passwords Turn on sign-in risk policy Do not allow users to grant consent to unmanaged applications Use Azure AD Identity Protection to detect, investigate, and remediate identity-based risks. To similarly protect your on-premises Active Directory domain, use Defender for Identity. | E3: IM-2 | F3: 5.4, 6.5 | G3: AC-2, AC-3, IA-2, IA-8, SI-4 | H3: 8.2, 8.3 | I3: IAM-05, IAM-06, IVS-05 | K3: 1. Is Azure AD Identity Secure Score reviewed and tracked for remediation? 2. Are Identity Protection policies (user risk, sign-in risk) enabled? 3. Is Microsoft Defender for Identity deployed to monitor on-premises AD for lateral movement, credential theft, and Kerberos abuse? 4. Is logging enabled for privileged role assignments and admin consent to applications? | L3: 1. Azure AD Identity Secure Score export (Azure Portal → Security → Identity Secure Score → Export). 2. Conditional Access and Identity Protection policy export (AzureAD PowerShell: Get-AzureADMSConditionalAccessPolicy). 3. Defender for Identity sensor deployment status (Defender for Identity Portal → Configuration → Sensors). 4. Azure AD Audit logs for role assignments (AzureAD PowerShell: Get-AzureADAuditDirectoryLogs). | M3: 4 | O3: Complete
A4: CSF-AZ-IM-03 | B4: Manage application identities securely and automatically | C4: Use managed application identities instead of creating human accounts for applications to access resources and execute code. Managed application identities provide benefits such as reducing the exposure of credentials. Automate the rotation of credentials to ensure the security of the identities. | D4: Use Azure managed identities, which can authenticate to Azure services and resources that support Azure AD authentication. Managed identity credentials are fully managed, rotated, and protected by the platform, avoiding hard-coded credentials in source code or configuration files. For services that don't support managed identities, use Azure AD to create a service principal with restricted permissions at the resource level. It is recommended to configure service principals with certificate credentials and fall back to client secrets for authentication. | E4: IM-3: | F4: N/A | G4: AC-2, AC-3, IA-4, IA-5, IA-9 | H4: N/A | I4: IAM-07, IAM-08, IAM-09 | K4: 1. Are Managed Identities used for applications instead of hard-coded credentials? 2. For applications that require service principals, are certificate-based credentials enforced over client secrets? 3. Is credential rotation automated via Key Vault? 4. Are service principal permissions restricted to least privilege? | L4: 1. List of resources with Managed Identities enabled (Azure CLI: az resource list --query "[?identity!=null]"). 2. Service principal credential types (Azure CLI: az ad sp credential list --id <AppID>). 3. Key Vault secret rotation policy JSON export (az keyvault secret show --vault-name <vault> --name <secret>). 4. Role assignments of service principals (Azure CLI: az role assignment list --assignee <AppID>) | M4: 4 | O4: Complete
A5: CSF-AZ-IM-04 | B5: Authenticate server and services | C5: Authenticate remote servers and services from your client side to ensure you are connecting to trusted server and services. The most common server authentication protocol is Transport Layer Security (TLS), where the client-side (often a browser or client device) verifies the server by verifying the server’s certificate was issued by a trusted certificate authority. | D5: Many Azure services support TLS authentication by default. For services that don't support TLS authentication by default, or support disabling TLS, ensure it is always enabled to support the server/client authentication. Your client application should also be designed to verify server/client identity (by verifying the server’s certificate issued by a trusted certificate authority) in the handshake stage. | E5: IM-4 | F5: N/A | G5: IA-9 | H5: N/A | I5: IAM-10, IAM-11, IAM-12 | K5: 1. Is HTTPS/TLS enforced on all Azure services (Storage, App Services, Key Vault)? 2. Are certificates issued from trusted CAs and stored in Azure Key Vault/App Service Certificates? 3. Is mutual TLS (mTLS) configured where service-to-service trust is required? 4. Are legacy/unencrypted protocols disabled (FTP, LDAP without TLS, HTTP)? | L5: 1. Azure Policy compliance report for “HTTPS Only” (Azure Policy → Assignments →Effect: Deny). 2. Key Vault certificate inventory export (az keyvault certificate list --vault-name <vault>). 3. App Gateway / API Management TLS configuration JSON. 4. List of enabled protocols per Storage account (az storage account show --name <storage> --query "enableHttpsTrafficOnly"). | M5: 4 | O5: Non-Compliant
A6: CSF-AZ-IM-05 | B6: Use single sign-on (SSO) for application access | C6: Use single sign-on (SSO) to simplify the user experience for authenticating to resources including applications and data across cloud services and on-premises environments. | D6: Use Azure AD for workload application access (customer facing) access through Azure AD single sign-on (SSO), reducing the need for duplicate accounts. Azure AD provides identity and access management to Azure resources (in the management plane, including CLI, PowerShell, the portal), cloud applications, and on-premises applications. | E6: IM-5 | F6: 12.5 | G6: IA-4, IA-2, IA-8 | H6: N/A | I6: IAM-13, IAM-14 | K6: 1. Are enterprise SaaS applications federated with Azure AD using SAML or OIDC? 2. Are guest users accessing apps via Azure AD B2B configured with Conditional Access policies? 3. Are any applications still using standalone logins outside Azure AD federation? | L6: 1. Enterprise Application list (AzureAD PowerShell: Get-AzureADServicePrincipal | Select DisplayName, AppId). 2. Federation settings for B2B/B2C (Azure AD → External Identities → Cross-tenant access). 3. Conditional Access policy assignments for SaaS apps. 4. Sign-in logs showing federated vs non-federated authentication (Azure Portal → Azure AD → Sign-ins) | M6: 4 | O6: Partial
A7: CSF-AZ-IM-06 | B7: Use strong authentication controls | C7: Enforce strong authentication controls (strong passwordless authentication or multi-factor authentication) with your centralized identity and authentication management system for all access to resources. Authentication based on password credentials alone is considered legacy, as it is insecure and does not stand up to popular attack methods. When deploying strong authentication, configure administrators and privileged users first, to ensure the highest level of the strong authentication method, quickly followed by rolling out the appropriate strong authentication policy to all users. | D7: Azure AD supports strong authentication controls through passwordless methods and multi-factor authentication (MFA). Passwordless authentication: Use passwordless authentication as your default authentication method. There are three options available in passwordless authentication: Windows Hello for Business, Microsoft Authenticator app phone sign-in, and FIDO2 security keys. In addition, customers can use on-premises authentication methods such as smart cards. Multi-factor authentication: Azure MFA can be enforced on all users, select users, or at the per-user level based on sign-in conditions and risk factors. Enable Azure MFA and follow Microsoft Defender for Cloud identity and access management recommendations for your MFA setup. If legacy password-based authentication is still used for Azure AD authentication, be aware that cloud-only accounts (user accounts created directly in Azure) have a default baseline password policy. And hybrid accounts (user accounts that come from on-premises Active Directory) follow the on-premises password policies. For third-party applications and services that may have default IDs and passwords, you should disable or change them during initial service setup. | E7: IM-6 | F7: 6.3, 6.4 | G7: AC-2, AC-3, IA-2, IA-5, IA-8 | H7: 7.2, 8.2, 8.3, 8.4 | I7: IAM-15, IAM-16 | K7: 1. Is MFA enforced for all privileged accounts and end users via Conditional Access? 2. Are passwordless authentication methods (FIDO2, Authenticator app, Windows Hello) enabled? 3. Is Azure AD Password Protection in place with custom banned password lists? 4. Are break-glass accounts exempt from MFA but monitored with alerts? | L7: 1. Conditional Access policies export (Get-AzureADMSConditionalAccessPolicy). 2. MFA registration report (Azure AD → Security → MFA → Registration Details). 3. Azure AD Password Protection policy configuration (Azure AD → Security → Authentication Methods → Password Protection). 4. Azure Monitor alerts for break-glass account usage. | M7: 4 | O7: Partial
A8: CSF-AZ-IM-07 | B8: Restrict resource access based on conditions | C8: Explicitly validate trusted signals to allow or deny user access to resources, as part of a zero-trust access model. Signals to validate should include strong authentication of user account, behavioral analytics of user account, device trustworthiness, user or group membership, locations and so on. | D8: Use Azure AD conditional access for more granular access controls based on user-defined conditions, such as requiring user logins from certain IP ranges (or devices) to use MFA. Azure AD Conditional Access allows you to enforce access controls on your organization’s apps based on certain conditions. Define the applicable conditions and criteria for Azure AD conditional access in the workload. Consider the following common use cases: Requiring multi-factor authentication for users with administrative roles Requiring multi-factor authentication for Azure management tasks Blocking sign-ins for users attempting to use legacy authentication protocols Requiring trusted locations for Azure AD Multi-Factor Authentication registration Blocking or granting access from specific locations Blocking risky sign-in behaviors Requiring organization-managed devices for specific applications Note: Granular authentication session management controls can also be implemented through Azure AD conditional access policy, such as sign-in frequency and persistent browser session. | E8: IM-7 | F8: 3.3, 6.4, 13.5 | G8: AC-2, AC-3, AC-6 | H8: 7.2 | I8: IAM-04, IAM-17 | K8: 1. Are Conditional Access policies applied based on device compliance (Intune), location, or risk level? 2. Are session controls (sign-in frequency, persistent browser sessions) enforced? 3. Are Conditional Access policies tested against high-risk users and applications? | L8: 1. Full Conditional Access policy JSON export. 2. Intune compliance policy configuration export. 3. Azure AD sign-in logs showing risk-based MFA enforcement. 4. Conditional Access “What-If” test results (Azure Portal → Conditional Access → What If). | M8: 4 | O8: Complete
A9: CSF-AZ-IM-08 | B9: Restrict the exposure of credentials and secrets | C9: Ensure that application developers securely handle credentials and secrets: Avoid embedding the credentials and secrets into the code and configuration files Use key vault or a secure key store service to store the credentials and secrets Scan for credentials in source code. | D9: When using a managed identity is not an option, ensure that secrets and credentials are stored in secure locations such as Azure Key Vault, instead of embedding them into the code and configuration files. If you use Azure DevOps and GitHub for your code management platform: Implement Azure DevOps Credential Scanner to identify credentials within the code. For GitHub, use the native secret scanning feature to identify credentials or other form of secrets within the code. Clients such as Azure Functions, Azure Apps services, and VMs can use managed identities to access Azure Key Vault securely. See Data Protection controls related to the use of Azure Key Vault for secrets management. Note: Azure Key Vault provides automatic rotation for supported services. For secrets that cannot be automatically rotated, ensure they are manually rotated periodically and purged when no longer in use. | E9: IM-8 | F9: 16.9, 16.12 | G9: IA-5 | H9: 3.5, 6.3, 8.2 | I9: IAM-18, IVS-02 | K9: 1. Are all application secrets, keys, and certificates stored in Azure Key Vault? 2. Is RBAC enforced for Key Vault access instead of using access policies only? 3. Are DevOps pipelines scanned for secrets (e.g., GitHub secret scanning, Microsoft Security DevOps)? 4. Are rotation schedules in place for secrets/certificates? 5. Are audit logs enabled for Key Vault access events? | L9: 1. Key Vault access policy and RBAC role assignment export (az keyvault show --name <vault> and az role assignment list). 2. Key Vault diagnostic settings showing logs sent to Log Analytics/Event Hub. 3. Secret scanning reports from GitHub/Azure DevOps. 4. Secret and certificate expiry/rotation configuration (az keyvault certificate list --vault-name <vault>). | M9: 4 | O9: Non-Compliant
A10: CSF-AZ-IM-09 | B10: Secure user access to existing applications | C10: In a hybrid environment, where you have on-premises applications or non-native cloud applications using legacy authentication, consider solutions such as cloud access security broker (CASB), application proxy, single sign-on (SSO) to govern the access to these applications for the following benefits: Enforce a centralized strong authentication Monitor and control risky end-user activities Monitor and remediate risky legacy applications activities Detect and prevent sensitive data transmission | D10: Protect your on-premises and non-native cloud applications using legacy authentication by connecting them to: Azure AD Application Proxy and configure header-based authentication to allow single sign-on (SSO) access to the applications for remote users, while explicitly validating the trustworthiness of both remote users and devices with Azure AD Conditional Access. If required, use a a third-party Software-Defined Perimeter (SDP) solution which can offer similar functionality. Microsoft Defender for Cloud Apps, which serves a cloud access security broker (CASB) service to monitor and block user access to unapproved third-party SaaS applications. Your existing third-party application delivery controllers and networks. | E10: IM-9 | F10: 6.7, 12.5 | G10: AC-2, AC-3, SC-11 | H10: N/A | I10: EKM-01, EKM-02, IAM-19 | K10: 1. Are Azure AD sign-in and audit logs integrated into Sentinel or another SIEM? 2. Are risky sign-ins, leaked credentials, and impossible travel events monitored? 3. Are automated remediation actions applied (MFA challenge, block, conditional access)? 4. Are deprecated accounts or stale service principals detected and alerted on? | L10: 1. Azure AD sign-in logs export (az ad signin list or Portal → Azure AD → Sign-ins). 2. Sentinel analytics rules for identity anomalies (Azure Sentinel → Analytics → Rule templates). 3. Identity Protection risky users/sign-ins export. 4. Reports of inactive accounts (Get-AzureADUser -All $true | ?{$_.AccountEnabled -eq $false}) | M10: 4 | O10: Non-Compliant
A11: CSF-AZ-IM-10 | B11: SSO utilized for most console/portal access | C11: Access to the CSP's console/portal is done through consolidated single sign-on. This can be via an external SSO provider or one built into the cloud platform. | D11: This is the default for Azure, which requires the use of Entra ID (formerly Azure AD) | J11: IAM-02.1 | K11: Is the organization currently following the Azure Guidance ? | L11: Confirmation of the Assessment question | M11: 1 | O11: Complete
A12: CSF-AZ-IM-11 | B12: Users do not access the cloud console/portal outside of SSO | C12: Access to the cloud console or portal is only through the SSO portal, with the exception of a break-glass account (in case the SSO integration breaks). | D12: This is the default for Azure, which requires the use of Entra ID | J12: IAM-03.1 | K12: Is the organization currently following the Azure Guidance ? | L12: Confirmation of the Assessment question | M12: 1 | O12: Complete
A13: CSF-AZ-IM-12 | B13: An IAM data perimeter is enforced | C13: An IAM data perimeter as an advanced concept that restricts where API calls are able to originate. While it may be implemented in all environments, it is especially important for production accounts. This is typically based on IP address but may also rely on device restrictions. Each cloud provider enforces these differently (and not all cloud providers support the capability at all), but the goal is to prevent an attacker from stealing static or session credentials (including tokens) and using them from a location under that attackers control. | D13: The subscription uses conditional access policies consistently | J13: IAM-05.1 | K13: Is the organization currently following the Azure Guidance ? | L13: Confirmation of the Assessment question | M13: 1 | O13: Partial
A14: CSF-AZ-IM-13 | B14: JIT access used for access to production deployments | C14: Rather than allowing persistent human access to cloud deployments, a just-in-time (JIT) system provisions time-limited, session-based access on demand. JIT requests must meet policy guidelines and the system must support out-of-band approvals for highly privileged access. | D14: Azure PIM is enabled and used on all production subscriptions | J14: IAM-05.2 | K14: Is the organization currently following the Azure Guidance ? | L14: Confirmation of the Assessment question | M14: 1 | O14: Complete

Sheet Privileged access
A1: Control ID | B1: Control Title | C1: Security Principle | D1: Azure Guidance | E1: MCSB Control ID Mapping | F1: CIS Mapping (v8) | G1: NIST SP 800-53 Mapping | H1: PCI-DSS Mapping (v3.2.1) | I1: CSA CCM Control ID | J1: Assessment Question | K1: Evidence to Collect | L1: Evidence Count | M1: Available Evidence Count | N1: Compliance Status | O1: Risk Severity (if non-compliant) | P1: Implementation Gap | Q1: Notes/Comments
A2: CSF-AZ-PA-01 | B2: Separate and limit highly privileged/administrative users | C2: Ensure you identify all high business impact accounts. Limit the number of privileged/administrative accounts in your cloud's control plane, management plane and data/workload plane. | D2: You must secure all roles with direct or indirect administrative access to Azure hosted resources. Azure Active Directory (Azure AD) is Azure's default identity and access management service. The most critical built-in roles in Azure AD are Global Administrator and Privileged Role Administrator, because users assigned to these two roles can delegate administrator roles. With these privileges, users can directly or indirectly read and modify every resource in your Azure environment: Global Administrator / Company Administrator: Users with this role have access to all administrative features in Azure AD as well as services that use Azure AD identities. Privileged Role Administrator: Users with this role can manage role assignments in Azure AD, as well as within Azure AD Privileged Identity Management (PIM). In addition, this role allows management of all aspects of PIM and administrative units. Outside of Azure AD, Azure has built-in roles that can be critical for privileged access at the resource level. Owner: Grants full access to manage all resources, including the ability to assign roles in Azure RBAC. Contributor: Grants full access to manage all resources, but does not allow you to assign roles in Azure RBAC, manage assignments in Azure Blueprints, or share image galleries. User Access Administrator: Lets you manage user access to Azure resources. Note: You may have other critical roles that need to be governed if you use custom roles in the Azure AD level or resource level with certain privileged permissions assigned. In addition, users with the following three roles in Azure Enterprise Agreement (EA) portal should also be restricted as they can be used to directly or indirectly manage Azure subscriptions. Account Owner: Users with this role can manage subscriptions, including the creation and deletion of subscriptions. Enterprise Administrator: Users assigned with this role can manage (EA) portal users. Department Administrator: Users assigned with this role can change account owners within the department. Lastly, ensure that you also restrict privileged accounts in other management, identity, and security systems that have administrative access to your business-critical assets, such as Active Directory Domain Controllers (DCs), security tools, and system management tools with agents installed on business-critical systems. Attackers who compromise these management and security systems can immediately weaponize them to compromise business critical assets. | E2: PA-1 | F2: 5.4, 6.8 | G2: AC-2, AC-6 | H2: 7.1, 7.2, 8.1 | I2: IAM-10, IAM-11, IAM-12 | J2: 1. Are Global Administrator and Privileged Role Administrator accounts restricted and minimized? 2. Are resource-level privileged roles (Owner, User Access Administrator) tightly controlled? 3. Are EA portal roles (Account Owner, Enterprise Administrator, Department Administrator) limited to authorized personnel? 4. Are custom roles reviewed for privileged permissions? | K2: 1. Export of all Azure AD role assignments (az role assignment list --all). 2. List of Global Administrators and Privileged Role Administrators (Get-AzureADDirectoryRole). 3. Access review report for EA portal roles. 4. RBAC role assignment JSON for custom roles. | L2: 4
A3: CSF-AZ-PA-02 | B3: Avoid standing access for user accounts and permissions | C3: Instead of creating standing privileges, use just-in-time (JIT) mechanism to assign privileged access to the different resource tiers. | D3: Enable just-in-time (JIT) privileged access to Azure resources and Azure AD using Azure AD Privileged Identity Management (PIM). JIT is a model in which users receive temporary permissions to perform privileged tasks, which prevents malicious or unauthorized users from gaining access after the permissions have expired. Access is granted only when users need it. PIM can also generate security alerts when there is suspicious or unsafe activity in your Azure AD organization. | E3: PA-2 | F3: N/A | G3: AC-2 | H3: N/A | I3: IAM-13, IAM-14 | J3: 1. Is Just-In-Time (JIT) access configured via Azure AD Privileged Identity Management (PIM)? 2. Are privileged role activations requiring approval and MFA? 3. Is JIT VM access enabled for administrative ports (RDP/SSH) via Microsoft Defender for Cloud? | K3: 1. PIM configuration export (Get-AzureADMSPrivilegedRoleSetting). 2. Role activation logs from PIM. 3. Defender for Cloud JIT VM access configuration export._x000D_ | L3: 3
A4: CSF-AZ-PA-03 | B4: Manage lifecycle of identities and entitlements | C4: Use an automated process or technical control to manage the identity and access lifecycle including the request, review, approval, provision, and deprovision. | D4: Use Azure AD entitlement management features to automate access request workflows (for Azure resource groups). This enables workflows for Azure resource groups to manage access assignments, reviews, expiration, and dual or multi-stage approval. | E4: PA-3 | F4: 6.1, 6.2 | G4: AC-5, AC-6 | H4: 7.1, 7.2, 8.1 | I4: IVS-04, IVS-09 | J4: 1. Are access request workflows configured with Azure AD Entitlement Management? 2. Are expiration and approval workflows enforced for resource group and application access? 3. Are unused or excessive entitlements detected and remediated with Permissions Management? | K4: 1. Entitlement Management access package configuration (Azure Portal → Identity Governance). 2. Access review reports (Get-AzureADMSAccessReview). 3. Permissions Management report on unused entitlementsm | L4: 3
A5: CSF-AZ-PA-04 | B5: Review and reconcile user access regularly | C5: Conduct regular review of privileged account entitlements. Ensure the access granted to the accounts are valid for administration of control plane, management plane, and workloads. | D5: Review all privileged accounts and the access entitlements in Azure including Azure tenants, Azure services, VM/IaaS, CI/CD processes, and enterprise management and security tools. Use Azure AD access reviews to review Azure AD roles, Azure resource access roles, group memberships, and access to enterprise applications. Azure AD reporting can also provide logs to help discover stale accounts, or accounts which have not been used for certain amount of time. In addition, Azure AD Privileged Identity Management can be configured to alert when an excessive number of administrator accounts are created for a specific role, and to identify administrator accounts that are stale or improperly configured. | E5: PA-4 | F5: 5.1, 5.3, 5.5 | G5: AC-2, AC-6 | H5: 7.1, 7.2, 8.1, A3.4 | I5: LOG-01, LOG-03, LOG-07 | J5: 1. Are periodic access reviews performed for Azure AD roles, resource access, and application entitlements? 2. Are stale or inactive accounts flagged and removed? 3. Are alerts configured for sudden increases in privileged accounts? | K5: 1. Azure AD Access Review reports. 2. Audit logs of account removal actions. 3. PIM configuration for admin count threshold alerts | L5: 3
A6: CSF-AZ-PA-05 | B6: Set up emergency access | C6: Set up emergency access to ensure that you are not accidentally locked out of your critical cloud infrastructure (such as your identity and access management system) in an emergency. Emergency access accounts should be rarely used and can be highly damaging to the organization if compromised, but their availability to the organization is also critically important for the few scenarios when they are required. | D6: To prevent being accidentally locked out of your Azure AD organization, set up an emergency access account (e.g., an account with Global Administrator role) for access when normal administrative accounts cannot be used. Emergency access accounts are usually highly privileged, and they should not be assigned to specific individuals. Emergency access accounts are limited to emergency or "break glass" scenarios where normal administrative accounts can't be used. You should ensure that the credentials (such as password, certificate, or smart card) for emergency access accounts are kept secure and known only to individuals who are authorized to use them only in an emergency. You may also use additional controls, such dual controls (e.g., splitting the credential into two pieces and giving it to separate persons) to enhance the security of this process. You should also monitor the sign-in and audit logs to ensure that emergency access accounts are only used when authorized. | E6: PA-5 | F6: N/A | G6: AC-2 | H6: N/A | I6: IAM-05, IAM-06, CCC-03 | J6: 1. Are at least two emergency access (break-glass) accounts created with Global Administrator role? 2. Are credentials stored securely (HSM, offline vault, split control)? 3. Are emergency account sign-ins monitored and alerted? 4. Are MFA exclusions documented only for break-glass accounts? | K6: 1. List of emergency accounts and their assigned roles. 2. Credential storage method documentation (Key Vault, password vault). 3. Azure AD sign-in logs filtered for emergency accounts. 4. Alert configuration for break-glass usage | L6: 4
